Workbook

Sheet MOTOR
A1: REPORTE DE ANÁLISIS DE LUBRICANTE
C2: NOMBRE DEL CLIENTE: | H2: Compartimento: | AA2: MOTOR | AH2: Diagnóstico de la última muestra:
H3: Equipo: | AA3: UG 00 | AH3: SIN EVALUACION
C4: JUSTICE COMPANY | H4: Marca: | AA4: MARCA EQUIPO | AH4: Degradación del lubricante aún no afecta al desgate. Se sugiere seguir con el monitoreo periódico de las condiciones del lubricante y del equipo.
H5: Serie: | AA5: SERIE
H6: Modelo: | AA6: MODELO
H7: Lubricante: | AA7: 15W40
H8: Marca del Lubricante: | AA8: GULF
B10: INFORMACIÓN DE LA MUESTRA
B12: Numeración de Muestra | C12: MUESTRA-001 | Y12: =Datos!X27
B13: Fecha de Muestreo | C13: 2026-03-28 | Y13: 46042
B14: Fecha de Ingreso | C14: 2026-03-29 | Y14: 46057
B15: Fecha de Informe | C15: 2026-03-30 | Y15: 46065
B16: Equipo Hrs/ Km | C16: 12000
B17: Aceite Hrs/ Km | C17: 320 | Y17: 519
B18: Condición | C18: NORMAL | Y18: ANORMAL
B20: ESTADO DEL LUBRICANTE | AC20: * Rangos Generales
AC21: Precaución | AE21: Anormal
B22: Viscosidad a 100ºC, cSt | C22: 0 | Y22: =(Datos!X30) | AB22: 0.15 | AC22: < | AD22: =AG22-(AG22*AB22) | AE22: > | AF22: =AG22+(AG22*AB22) | AG22: 14.5
B23: Viscosidad a 40ºC, cSt | C23: 0 | Y23: =(Datos!X31) | AC23: < | AD23: 97.2 | AE23: > | AF23: 124.2
B24: Indice de Viscosidad | C24: 0 | Y24: =(Datos!X32) | AD24: -- | AF24: --
B25: T.B.N. mgKOH/gr | C25: 0 | Y25: =(Datos!X31) | AC25: [50% TBN -1]
B26: Humedad | C26: NEGATIVO | Y26: NEGATIVO | AD26: -- | AE26: POSITIVO
B27: Glycol, Abs/cm | C27: 0 | AD27: -- | AE27: ≥ | AF27: 2
B28: Combustible | C28: NEGATIVO | AD28: -- | AE28: POSITIVO
B30: DEGRADACIÓN QUÍMICA | AC30: * Rangos Generales
AC31: Precaución | AE31: Anormal
B32: Oxidación, Abs/cm | C32: 0 | Y32: =(Datos!X35) | AC32: ≥ | AD32: 18 | AE32: ≥ | AF32: 20
B33: Nitración, Abs/cm | C33: 0 | Y33: =(Datos!X34) | AC33: ≥ | AD33: 15 | AE33: ≥ | AF33: 20
B34: Sulfatación, Abs/cm | C34: 0 | Y34: =(Datos!X33) | AC34: ≥ | AD34: 25 | AE34: ≥ | AF34: 32
B35: Hollín, wt% | C35: 0 | Y35: =(Datos!X32) | AC35: ≥ | AD35: 2 | AE35: ≥ | AF35: 3
B37: CONTAMINACIÓN DEL LUBRICANTE - PPM (mg/kg) | AC37: * Rangos Generales
AC38: Precaución | AE38: Anormal
B39: Si (Silicio) | C39: 0 | Y39: =Datos!X7 | AC39: ≥ | AD39: 16 | AE39: ≥ | AF39: 20
B40: Na (Sodio) | C40: 0 | Y40: =Datos!X15 | AC40: ≥ | AD40: 16 | AE40: ≥ | AF40: 30
B41: Vanadio (V) | C41: 0 | Y41: =Datos!X17 | AC41: ≥ | AD41: 30 | AE41: ≥ | AF41: 50
B42: Ni (Niquel) | C42: 0 | Y42: =Datos!X16 | AD42: -- | AE42: ≥ | AF42: 20
B44: DESGATE DEL EQUIPO - PPM (mg/kg) | AC44: * Rangos Generales
AC45: Precaución | AE45: Anormal
B46: Fe (Hierro) | C46: 0 | Y46: =Datos!X3 | AC46: ≥ | AD46: 100 | AE46: ≥ | AF46: 190
...

Sheet INDUSTRTIAL
A1: REPORTE DE ANÁLISIS DE LUBRICANTE
C2: NOMBRE DEL CLIENTE: | H2: Compartimento: | L2: =Datos!A97 | S2: Diagnóstico de la última muestra: | AA2: INDUSTRTIAL
H3: Equipo: | L3: =MOTOR!AA3 | S3: SIN EVALUACIÓN | AA3: UG 00 | AH3: SIN EVALUACION
C4: JUSTICE COMPANY | H4: Marca: | L4: =MOTOR!AA4 | AA4: MARCA EQUIPO
H5: Serie: | L5: =MOTOR!AA5 | AA5: SERIE
H6: Modelo: | L6: =MOTOR!AA6 | AA6: MODELO
H7: Lubricante: | AA7: 15W40
H8: Marca del Lubricante: | AA8: GULF
B10: INFORMACIÓN DE LA MUESTRA
B12: Numeración de Muestra | C12: MUESTRA-001
B13: Fecha de Muestreo | C13: 2026-03-28
B14: Fecha de Ingreso | C14: 2026-03-29
B15: Fecha de Informe | C15: 2026-03-30
B16: Equipo Hrs/ Km | C16: 12000
B17: Aceite Hrs/ Km | C17: 320
B18: Condición | C18: NORMAL
B20: ESTADO DEL LUBRICANTE | N20: * Rangos Generales
N21: Precaución | P21: Anormal
B22: Viscosidad a 100ºC, cSt | C22: 0
B23: Viscosidad a 40ºC, cSt | C23: 0
B24: Indice de Viscosidad | C24: 0
B25: T.B.N. mgKOH/gr | C25: 0 | N25: [50% TBN -1]
B26: Humedad | C26: NEGATIVO | P26: POSITIVO
B27: Glycol, Abs/cm | C27: 0
B28: Combustible | C28: NEGATIVO | P28: POSITIVO
B30: DEGRADACIÓN QUÍMICA | N30: * Rangos Generales
N31: Precaución | P31: Anormal
B32: Oxidación, Abs/cm | C32: 0
B33: Nitración, Abs/cm | C33: 0
B34: Sulfatación, Abs/cm | C34: 0
B35: Hollín, wt% | C35: 0
B37: CONTAMINACIÓN DEL LUBRICANTE - PPM (mg/kg) | N37: * Rangos Generales
N38: Precaución | P38: Anormal
B39: Si (Silicio) | C39: 0
B40: Na (Sodio) | C40: 0
B41: Vanadio (V) | C41: 0
B42: Ni (Niquel) | C42: 0
B44: DESGATE DEL EQUIPO - PPM (mg/kg) | N44: * Rangos Generales
N45: Precaución | P45: Anormal
B46: Fe (Hierro) | C46: 0
...

Sheet DIFERENCIAL DELANTERO
A1: REPORTE DE ANÁLISIS DE LUBRICANTE
C2: NOMBRE DEL CLIENTE: | H2: Compartimento: | L2: =Datos!A126 | S2: Diagnóstico de la última muestra: | AA2: DIFERENCIAL DELANTERO
H3: Equipo: | L3: =MOTOR!AA3 | S3: SIN EVALUACIÓN | AA3: UG 00 | AH3: SIN EVALUACION
C4: JUSTICE COMPANY | H4: Marca: | L4: =MOTOR!AA4 | AA4: MARCA EQUIPO
H5: Serie: | L5: =MOTOR!AA5 | AA5: SERIE
H6: Modelo: | L6: =MOTOR!AA6 | AA6: MODELO
H7: Lubricante: | AA7: 15W40
H8: Marca del Lubricante: | AA8: GULF
B10: INFORMACIÓN DE LA MUESTRA
B12: Numeración de Muestra | C12: MUESTRA-001
B13: Fecha de Muestreo | C13: 2026-03-28
B14: Fecha de Ingreso | C14: 2026-03-29
B15: Fecha de Informe | C15: 2026-03-30
B16: Equipo Hrs/ Km | C16: 12000
B17: Aceite Hrs/ Km | C17: 320
B18: Condición | C18: NORMAL
B20: ESTADO DEL LUBRICANTE | N20: * Rangos Generales
N21: Precaución | P21: Anormal
B22: Viscosidad a 100ºC, cSt | C22: 0
B23: Viscosidad a 40ºC, cSt | C23: 0
B24: Indice de Viscosidad | C24: 0
B25: T.B.N. mgKOH/gr | C25: 0 | N25: [50% TBN -1]
B26: Humedad | C26: NEGATIVO | P26: POSITIVO
B27: Glycol, Abs/cm | C27: 0
B28: Combustible | C28: NEGATIVO | P28: POSITIVO
B30: DEGRADACIÓN QUÍMICA | N30: * Rangos Generales
N31: Precaución | P31: Anormal
B32: Oxidación, Abs/cm | C32: 0
B33: Nitración, Abs/cm | C33: 0
B34: Sulfatación, Abs/cm | C34: 0
B35: Hollín, wt% | C35: 0
B37: CONTAMINACIÓN DEL LUBRICANTE - PPM (mg/kg) | N37: * Rangos Generales
N38: Precaución | P38: Anormal
B39: Si (Silicio) | C39: 0
B40: Na (Sodio) | C40: 0
B41: Vanadio (V) | C41: 0
B42: Ni (Niquel) | C42: 0
B44: DESGATE DEL EQUIPO - PPM (mg/kg) | N44: * Rangos Generales
N45: Precaución | P45: Anormal
B46: Fe (Hierro) | C46: 0
...

Sheet DIFERENCIAL POSTERIOR
A1: REPORTE DE ANÁLISIS DE LUBRICANTE
C2: NOMBRE DEL CLIENTE: | H2: Compartimento: | L2: =Datos!A155 | S2: Diagnóstico de la última muestra: | AA2: DIFERENCIAL POSTERIOR
H3: Equipo: | L3: =MOTOR!AA3 | S3: SIN EVALUACIÓN | AA3: UG 00 | AH3: SIN EVALUACION
C4: JUSTICE COMPANY | H4: Marca: | L4: =MOTOR!AA4 | AA4: MARCA EQUIPO
H5: Serie: | L5: =MOTOR!AA5 | AA5: SERIE
H6: Modelo: | L6: =MOTOR!AA6 | AA6: MODELO
H7: Lubricante: | AA7: 15W40
H8: Marca del Lubricante: | AA8: GULF
B10: INFORMACIÓN DE LA MUESTRA
B12: Numeración de Muestra | C12: MUESTRA-001
B13: Fecha de Muestreo | C13: 2026-03-28
B14: Fecha de Ingreso | C14: 2026-03-29
B15: Fecha de Informe | C15: 2026-03-30
B16: Equipo Hrs/ Km | C16: 12000
B17: Aceite Hrs/ Km | C17: 320
B18: Condición | C18: NORMAL
B20: ESTADO DEL LUBRICANTE | N20: * Rangos Generales
N21: Precaución | P21: Anormal
B22: Viscosidad a 100ºC, cSt | C22: 0
B23: Viscosidad a 40ºC, cSt | C23: 0
B24: Indice de Viscosidad | C24: 0
B25: T.B.N. mgKOH/gr | C25: 0 | N25: [50% TBN -1]
B26: Humedad | C26: NEGATIVO | P26: POSITIVO
B27: Glycol, Abs/cm | C27: 0
B28: Combustible | C28: NEGATIVO | P28: POSITIVO
B30: DEGRADACIÓN QUÍMICA | N30: * Rangos Generales
N31: Precaución | P31: Anormal
B32: Oxidación, Abs/cm | C32: 0
B33: Nitración, Abs/cm | C33: 0
B34: Sulfatación, Abs/cm | C34: 0
B35: Hollín, wt% | C35: 0
B37: CONTAMINACIÓN DEL LUBRICANTE - PPM (mg/kg) | N37: * Rangos Generales
N38: Precaución | P38: Anormal
B39: Si (Silicio) | C39: 0
B40: Na (Sodio) | C40: 0
B41: Vanadio (V) | C41: 0
B42: Ni (Niquel) | C42: 0
B44: DESGATE DEL EQUIPO - PPM (mg/kg) | N44: * Rangos Generales
N45: Precaución | P45: Anormal
B46: Fe (Hierro) | C46: 0
...

Sheet SWING
A1: REPORTE DE ANÁLISIS DE LUBRICANTE
C2: NOMBRE DEL CLIENTE: | H2: Compartimento: | L2: =Datos!A184 | S2: Diagnóstico de la última muestra: | AA2: SWING
H3: Equipo: | L3: =MOTOR!AA3 | S3: SIN EVALUACIÓN | AA3: UG 00 | AH3: SIN EVALUACION
C4: JUSTICE COMPANY | H4: Marca: | L4: =MOTOR!AA4 | AA4: MARCA EQUIPO
H5: Serie: | L5: =MOTOR!AA5 | AA5: SERIE
H6: Modelo: | L6: =MOTOR!AA6 | AA6: MODELO
H7: Lubricante: | AA7: 15W40
H8: Marca del Lubricante: | AA8: GULF
B10: INFORMACIÓN DE LA MUESTRA
B12: Numeración de Muestra | C12: MUESTRA-001
B13: Fecha de Muestreo | C13: 2026-03-28
B14: Fecha de Ingreso | C14: 2026-03-29
B15: Fecha de Informe | C15: 2026-03-30
B16: Equipo Hrs/ Km | C16: 12000
B17: Aceite Hrs/ Km | C17: 320
B18: Condición | C18: NORMAL
B20: ESTADO DEL LUBRICANTE | N20: * Rangos Generales
N21: Precaución | P21: Anormal
B22: Viscosidad a 100ºC, cSt | C22: 0
B23: Viscosidad a 40ºC, cSt | C23: 0
B24: Indice de Viscosidad | C24: 0
B25: T.B.N. mgKOH/gr | C25: 0 | N25: [50% TBN -1]
B26: Humedad | C26: NEGATIVO | P26: POSITIVO
B27: Glycol, Abs/cm | C27: 0
B28: Combustible | C28: NEGATIVO | P28: POSITIVO
B30: DEGRADACIÓN QUÍMICA | N30: * Rangos Generales
N31: Precaución | P31: Anormal
B32: Oxidación, Abs/cm | C32: 0
B33: Nitración, Abs/cm | C33: 0
B34: Sulfatación, Abs/cm | C34: 0
B35: Hollín, wt% | C35: 0
B37: CONTAMINACIÓN DEL LUBRICANTE - PPM (mg/kg) | N37: * Rangos Generales
N38: Precaución | P38: Anormal
B39: Si (Silicio) | C39: 0
B40: Na (Sodio) | C40: 0
B41: Vanadio (V) | C41: 0
B42: Ni (Niquel) | C42: 0
B44: DESGATE DEL EQUIPO - PPM (mg/kg) | N44: * Rangos Generales
N45: Precaución | P45: Anormal
B46: Fe (Hierro) | C46: 0
...

Sheet ENGRANAJE DE LA BOMBA
A1: REPORTE DE ANÁLISIS DE LUBRICANTE
C2: NOMBRE DEL CLIENTE: | H2: Compartimento: | L2: =Datos!A213 | S2: Diagnóstico de la última muestra: | AA2: ENGRANAJE DE LA BOMBA
H3: Equipo: | L3: =MOTOR!AA3 | S3: SIN EVALUACIÓN | AA3: UG 00 | AH3: SIN EVALUACION
C4: JUSTICE COMPANY | H4: Marca: | L4: =MOTOR!AA4 | AA4: MARCA EQUIPO
H5: Serie: | L5: =MOTOR!AA5 | AA5: SERIE
H6: Modelo: | L6: =MOTOR!AA6 | AA6: MODELO
H7: Lubricante: | AA7: 15W40
H8: Marca del Lubricante: | AA8: GULF
B10: INFORMACIÓN DE LA MUESTRA
B12: Numeración de Muestra | C12: MUESTRA-001
B13: Fecha de Muestreo | C13: 2026-03-28
B14: Fecha de Ingreso | C14: 2026-03-29
B15: Fecha de Informe | C15: 2026-03-30
B16: Equipo Hrs/ Km | C16: 12000
B17: Aceite Hrs/ Km | C17: 320
B18: Condición | C18: NORMAL
B20: ESTADO DEL LUBRICANTE | N20: * Rangos Generales
N21: Precaución | P21: Anormal
B22: Viscosidad a 100ºC, cSt | C22: 0
B23: Viscosidad a 40ºC, cSt | C23: 0
B24: Indice de Viscosidad | C24: 0
B25: T.B.N. mgKOH/gr | C25: 0 | N25: [50% TBN -1]
B26: Humedad | C26: NEGATIVO | P26: POSITIVO
B27: Glycol, Abs/cm | C27: 0
B28: Combustible | C28: NEGATIVO | P28: POSITIVO
B30: DEGRADACIÓN QUÍMICA | N30: * Rangos Generales
N31: Precaución | P31: Anormal
B32: Oxidación, Abs/cm | C32: 0
B33: Nitración, Abs/cm | C33: 0
B34: Sulfatación, Abs/cm | C34: 0
B35: Hollín, wt% | C35: 0
B37: CONTAMINACIÓN DEL LUBRICANTE - PPM (mg/kg) | N37: * Rangos Generales
N38: Precaución | P38: Anormal
B39: Si (Silicio) | C39: 0
B40: Na (Sodio) | C40: 0
B41: Vanadio (V) | C41: 0
B42: Ni (Niquel) | C42: 0
B44: DESGATE DEL EQUIPO - PPM (mg/kg) | N44: * Rangos Generales
N45: Precaución | P45: Anormal
B46: Fe (Hierro) | C46: 0
...

Sheet MANDO FINAL DERECHO
A1: REPORTE DE ANÁLISIS DE LUBRICANTE
C2: NOMBRE DEL CLIENTE: | H2: Compartimento: | L2: =Datos!A242 | S2: Diagnóstico de la última muestra: | AA2: MANDO FINAL DERECHO
H3: Equipo: | L3: =MOTOR!AA3 | S3: SIN EVALUACIÓN | AA3: UG 00 | AH3: SIN EVALUACION
C4: JUSTICE COMPANY | H4: Marca: | L4: =MOTOR!AA4 | AA4: MARCA EQUIPO
H5: Serie: | L5: =MOTOR!AA5 | AA5: SERIE
H6: Modelo: | L6: =MOTOR!AA6 | AA6: MODELO
H7: Lubricante: | AA7: 15W40
H8: Marca del Lubricante: | AA8: GULF
B10: INFORMACIÓN DE LA MUESTRA
B12: Numeración de Muestra | C12: MUESTRA-001
B13: Fecha de Muestreo | C13: 2026-03-28
B14: Fecha de Ingreso | C14: 2026-03-29
B15: Fecha de Informe | C15: 2026-03-30
B16: Equipo Hrs/ Km | C16: 12000
B17: Aceite Hrs/ Km | C17: 320
B18: Condición | C18: NORMAL
B20: ESTADO DEL LUBRICANTE | N20: * Rangos Generales
N21: Precaución | P21: Anormal
B22: Viscosidad a 100ºC, cSt | C22: 0
B23: Viscosidad a 40ºC, cSt | C23: 0
B24: Indice de Viscosidad | C24: 0
B25: T.B.N. mgKOH/gr | C25: 0 | N25: [50% TBN -1]
B26: Humedad | C26: NEGATIVO | P26: POSITIVO
B27: Glycol, Abs/cm | C27: 0
B28: Combustible | C28: NEGATIVO | P28: POSITIVO
B30: DEGRADACIÓN QUÍMICA | N30: * Rangos Generales
N31: Precaución | P31: Anormal
B32: Oxidación, Abs/cm | C32: 0
B33: Nitración, Abs/cm | C33: 0
B34: Sulfatación, Abs/cm | C34: 0
B35: Hollín, wt% | C35: 0
B37: CONTAMINACIÓN DEL LUBRICANTE - PPM (mg/kg) | N37: * Rangos Generales
N38: Precaución | P38: Anormal
B39: Si (Silicio) | C39: 0
B40: Na (Sodio) | C40: 0
B41: Vanadio (V) | C41: 0
B42: Ni (Niquel) | C42: 0
B44: DESGATE DEL EQUIPO - PPM (mg/kg) | N44: * Rangos Generales
N45: Precaución | P45: Anormal
B46: Fe (Hierro) | C46: 0
...

Sheet MANDO FINAL IZQUIERDO
A1: REPORTE DE ANÁLISIS DE LUBRICANTE
C2: NOMBRE DEL CLIENTE: | H2: Compartimento: | L2: =Datos!A271 | S2: Diagnóstico de la última muestra: | AA2: MANDO FINAL IZQUIERDO
H3: Equipo: | L3: =MOTOR!AA3 | S3: SIN EVALUACIÓN | AA3: UG 00 | AH3: SIN EVALUACION
C4: JUSTICE COMPANY | H4: Marca: | L4: =MOTOR!AA4 | AA4: MARCA EQUIPO
H5: Serie: | L5: =MOTOR!AA5 | AA5: SERIE
H6: Modelo: | L6: =MOTOR!AA6 | AA6: MODELO
H7: Lubricante: | AA7: 15W40
H8: Marca del Lubricante: | AA8: GULF
B10: INFORMACIÓN DE LA MUESTRA
B12: Numeración de Muestra | C12: MUESTRA-001
B13: Fecha de Muestreo | C13: 2026-03-28
B14: Fecha de Ingreso | C14: 2026-03-29
B15: Fecha de Informe | C15: 2026-03-30
B16: Equipo Hrs/ Km | C16: 12000
B17: Aceite Hrs/ Km | C17: 320
B18: Condición | C18: NORMAL
B20: ESTADO DEL LUBRICANTE | N20: * Rangos Generales
N21: Precaución | P21: Anormal
B22: Viscosidad a 100ºC, cSt | C22: 0
B23: Viscosidad a 40ºC, cSt | C23: 0
B24: Indice de Viscosidad | C24: 0
B25: T.B.N. mgKOH/gr | C25: 0 | N25: [50% TBN -1]
B26: Humedad | C26: NEGATIVO | P26: POSITIVO
B27: Glycol, Abs/cm | C27: 0
B28: Combustible | C28: NEGATIVO | P28: POSITIVO
B30: DEGRADACIÓN QUÍMICA | N30: * Rangos Generales
N31: Precaución | P31: Anormal
B32: Oxidación, Abs/cm | C32: 0
B33: Nitración, Abs/cm | C33: 0
B34: Sulfatación, Abs/cm | C34: 0
B35: Hollín, wt% | C35: 0
B37: CONTAMINACIÓN DEL LUBRICANTE - PPM (mg/kg) | N37: * Rangos Generales
N38: Precaución | P38: Anormal
B39: Si (Silicio) | C39: 0
B40: Na (Sodio) | C40: 0
B41: Vanadio (V) | C41: 0
B42: Ni (Niquel) | C42: 0
B44: DESGATE DEL EQUIPO - PPM (mg/kg) | N44: * Rangos Generales
N45: Precaución | P45: Anormal
B46: Fe (Hierro) | C46: 0
...

Sheet TANDEM DERECHO
A1: REPORTE DE ANÁLISIS DE LUBRICANTE
C2: NOMBRE DEL CLIENTE: | H2: Compartimento: | L2: =Datos!A300 | S2: Diagnóstico de la última muestra: | AA2: TANDEM DERECHO
H3: Equipo: | L3: =MOTOR!AA3 | S3: SIN EVALUACIÓN | AA3: UG 00 | AH3: SIN EVALUACION
C4: JUSTICE COMPANY | H4: Marca: | L4: =MOTOR!AA4 | AA4: MARCA EQUIPO
H5: Serie: | L5: =MOTOR!AA5 | AA5: SERIE
H6: Modelo: | L6: =MOTOR!AA6 | AA6: MODELO
H7: Lubricante: | AA7: 15W40
H8: Marca del Lubricante: | AA8: GULF
B10: INFORMACIÓN DE LA MUESTRA
B12: Numeración de Muestra | C12: MUESTRA-001
B13: Fecha de Muestreo | C13: 2026-03-28
B14: Fecha de Ingreso | C14: 2026-03-29
B15: Fecha de Informe | C15: 2026-03-30
B16: Equipo Hrs/ Km | C16: 12000
B17: Aceite Hrs/ Km | C17: 320
B18: Condición | C18: NORMAL
B20: ESTADO DEL LUBRICANTE | N20: * Rangos Generales
N21: Precaución | P21: Anormal
B22: Viscosidad a 100ºC, cSt | C22: 0
B23: Viscosidad a 40ºC, cSt | C23: 0
B24: Indice de Viscosidad | C24: 0
B25: T.B.N. mgKOH/gr | C25: 0 | N25: [50% TBN -1]
B26: Humedad | C26: NEGATIVO | P26: POSITIVO
B27: Glycol, Abs/cm | C27: 0
B28: Combustible | C28: NEGATIVO | P28: POSITIVO
B30: DEGRADACIÓN QUÍMICA | N30: * Rangos Generales
N31: Precaución | P31: Anormal
B32: Oxidación, Abs/cm | C32: 0
B33: Nitración, Abs/cm | C33: 0
B34: Sulfatación, Abs/cm | C34: 0
B35: Hollín, wt% | C35: 0
B37: CONTAMINACIÓN DEL LUBRICANTE - PPM (mg/kg) | N37: * Rangos Generales
N38: Precaución | P38: Anormal
B39: Si (Silicio) | C39: 0
B40: Na (Sodio) | C40: 0
B41: Vanadio (V) | C41: 0
B42: Ni (Niquel) | C42: 0
B44: DESGATE DEL EQUIPO - PPM (mg/kg) | N44: * Rangos Generales
N45: Precaución | P45: Anormal
B46: Fe (Hierro) | C46: 0
...

Sheet TANDEM IZQUIERDO
A1: REPORTE DE ANÁLISIS DE LUBRICANTE
C2: NOMBRE DEL CLIENTE: | H2: Compartimento: | L2: =Datos!A329 | S2: Diagnóstico de la última muestra: | AA2: TANDEM IZQUIERDO
H3: Equipo: | L3: =MOTOR!AA3 | S3: SIN EVALUACIÓN | AA3: UG 00 | AH3: SIN EVALUACION
C4: JUSTICE COMPANY | H4: Marca: | L4: =MOTOR!AA4 | AA4: MARCA EQUIPO
H5: Serie: | L5: =MOTOR!AA5 | AA5: SERIE
H6: Modelo: | L6: =MOTOR!AA6 | AA6: MODELO
H7: Lubricante: | AA7: 15W40
H8: Marca del Lubricante: | AA8: GULF
B10: INFORMACIÓN DE LA MUESTRA
B12: Numeración de Muestra | C12: MUESTRA-001
B13: Fecha de Muestreo | C13: 2026-03-28
B14: Fecha de Ingreso | C14: 2026-03-29
B15: Fecha de Informe | C15: 2026-03-30
B16: Equipo Hrs/ Km | C16: 12000
B17: Aceite Hrs/ Km | C17: 320
B18: Condición | C18: NORMAL
B20: ESTADO DEL LUBRICANTE | N20: * Rangos Generales
N21: Precaución | P21: Anormal
B22: Viscosidad a 100ºC, cSt | C22: 0
B23: Viscosidad a 40ºC, cSt | C23: 0
B24: Indice de Viscosidad | C24: 0
B25: T.B.N. mgKOH/gr | C25: 0 | N25: [50% TBN -1]
B26: Humedad | C26: NEGATIVO | P26: POSITIVO
B27: Glycol, Abs/cm | C27: 0
B28: Combustible | C28: NEGATIVO | P28: POSITIVO
B30: DEGRADACIÓN QUÍMICA | N30: * Rangos Generales
N31: Precaución | P31: Anormal
B32: Oxidación, Abs/cm | C32: 0
B33: Nitración, Abs/cm | C33: 0
B34: Sulfatación, Abs/cm | C34: 0
B35: Hollín, wt% | C35: 0
B37: CONTAMINACIÓN DEL LUBRICANTE - PPM (mg/kg) | N37: * Rangos Generales
N38: Precaución | P38: Anormal
B39: Si (Silicio) | C39: 0
B40: Na (Sodio) | C40: 0
B41: Vanadio (V) | C41: 0
B42: Ni (Niquel) | C42: 0
B44: DESGATE DEL EQUIPO - PPM (mg/kg) | N44: * Rangos Generales
N45: Precaución | P45: Anormal
B46: Fe (Hierro) | C46: 0
...

Sheet Instructivo
B1: INSTRUCTIVO PARA REPORTE DE ENSAYO. | M1: Pag 1 de 1
A9: Lab-Lubrisa con el propósito de brindar un mejor servicio POST-VENTA ha optado por mejorar su reporte de ensayos para las muestras de aceite usado. Por ellos en este documento se detalla las actualizaciones de este reporte:
A12: Para llevar un seguimiento a las muestras que se analizan es necesario que la información que se proporciona en las etiquetas sea la correcta y completa, ya que forma parte del encabezado de reporte de ensayo y en la posterioridad nuevas muestras sean reportadas en el mismo informe.
A26: A continuación se reportan los resultados obtenidos según el tipo de aceite ha analizar: MOTOR - CARTER HIDRÁULICOS INDUSTRIAL
A58: Para los resultados ingresado: Cuando un párametro no se encuentra dentro de los rangos generales, este resultado automaticamente se cambiara de color con la finalidad de que sea facilmente identificable su Anormalidad.
A83: En la parte superior derecha del reporte se mostrará una evaluación visual en base a la ultima muestra analizada, que puede presentarse de las siguientes formas:
A86: Evaluación de ultima muestra: | B86: SIN EVALUACIÓN | C86: No se ha realizado la evaluación correspondiente
B87: PARAMETROS NORMALES | C87: Todos los parametros se encuentra dentro de los rangos generales
B88: PRECAUCIÓN | C88: Uno o varios parametros se encuentran dentro de lo tolerable, por lo cual se debe tomar una accion preventiva.
B89: PARAMETROS ANORMALES | C89: Uno o varios parametros se encuentra fuera de los rangos generales
